<?xml version="1.0" ?>
<robot name="rhexa" xmlns:xacro="http://www.ros.org/wiki/xacro">

<xacro:include filename="$(find rhexa_description)/urdf/materials.xacro" />
<xacro:include filename="$(find rhexa_description)/urdf/rhexa.trans" />
<xacro:include filename="$(find rhexa_description)/urdf/rhexa.gazebo" />
<link name="base_link">
  <inertial>
    <origin xyz="3.019715383457247e-11 3.0286398058123193e-12 0.04300979484933489" rpy="0 0 0"/>
    <mass value="4.071597447876389"/>
    <inertia ixx="0.006647" iyy="0.00646" izz="0.007974" ixy="-0.0" iyz="0.0" ixz="0.0"/>
  </inertial>
  <visual>
    <origin xyz="0 0 0" rpy="0 0 0"/>
    <geometry>
      <mesh filename="package://rhexa_description/meshes/base_link.stl" scale="0.001 0.001 0.001"/>
    </geometry>
    <material name="silver"/>
  </visual>
  <collision>
    <origin xyz="0 0 0" rpy="0 0 0"/>
    <geometry>
      <mesh filename="package://rhexa_description/meshes/base_link.stl" scale="0.001 0.001 0.001"/>
    </geometry>
  </collision>
</link>

<link name="Componente5_1">
  <inertial>
    <origin xyz="-6.551741014804067e-15 0.0 -0.029302995324400033" rpy="0 0 0"/>
    <mass value="1.4329758168878506"/>
    <inertia ixx="0.00077" iyy="0.0009" izz="0.000718" ixy="-0.0" iyz="0.0" ixz="0.0"/>
  </inertial>
  <visual>
    <origin xyz="-0.0 -0.0 -0.07" rpy="0 0 0"/>
    <geometry>
      <mesh filename="package://rhexa_description/meshes/Componente5_1.stl" scale="0.001 0.001 0.001"/>
    </geometry>
    <material name="silver"/>
  </visual>
  <collision>
    <origin xyz="-0.0 -0.0 -0.07" rpy="0 0 0"/>
    <geometry>
      <mesh filename="package://rhexa_description/meshes/Componente5_1.stl" scale="0.001 0.001 0.001"/>
    </geometry>
  </collision>
</link>

<link name="Joint1_1">
  <inertial>
    <origin xyz="-0.005063577162265159 0.00802518126873147 0.017718296440327963" rpy="0 0 0"/>
    <mass value="0.4253453909942233"/>
    <inertia ixx="0.000187" iyy="0.000136" izz="0.000223" ixy="4.4e-05" iyz="-5.1e-05" ixz="2.6e-05"/>
  </inertial>
  <visual>
    <origin xyz="-0.0 -0.0 -0.09" rpy="0 0 0"/>
    <geometry>
      <mesh filename="package://rhexa_description/meshes/Joint1_1.stl" scale="0.001 0.001 0.001"/>
    </geometry>
    <material name="silver"/>
  </visual>
  <collision>
    <origin xyz="-0.0 -0.0 -0.09" rpy="0 0 0"/>
    <geometry>
      <mesh filename="package://rhexa_description/meshes/Joint1_1.stl" scale="0.001 0.001 0.001"/>
    </geometry>
  </collision>
</link>

<link name="Joint2_1">
  <inertial>
    <origin xyz="0.038661806510004754 0.09997431201439586 0.002273424469393992" rpy="0 0 0"/>
    <mass value="1.6609996524765318"/>
    <inertia ixx="0.009226" iyy="0.000656" izz="0.00941" ixy="-0.0" iyz="-0.000199" ixz="0.0"/>
  </inertial>
  <visual>
    <origin xyz="0.016501 -0.035737 -0.126223" rpy="0 0 0"/>
    <geometry>
      <mesh filename="package://rhexa_description/meshes/Joint2_1.stl" scale="0.001 0.001 0.001"/>
    </geometry>
    <material name="silver"/>
  </visual>
  <collision>
    <origin xyz="0.016501 -0.035737 -0.126223" rpy="0 0 0"/>
    <geometry>
      <mesh filename="package://rhexa_description/meshes/Joint2_1.stl" scale="0.001 0.001 0.001"/>
    </geometry>
  </collision>
</link>

<link name="Joint3_1">
  <inertial>
    <origin xyz="-0.035345273786924564 0.07500047440104876 4.961988451512855e-07" rpy="0 0 0"/>
    <mass value="0.2466726132340227"/>
    <inertia ixx="0.000815" iyy="6.7e-05" izz="0.000852" ixy="0.0" iyz="0.0" ixz="0.0"/>
  </inertial>
  <visual>
    <origin xyz="-0.01783 -0.235685 -0.130769" rpy="0 0 0"/>
    <geometry>
      <mesh filename="package://rhexa_description/meshes/Joint3_1.stl" scale="0.001 0.001 0.001"/>
    </geometry>
    <material name="silver"/>
  </visual>
  <collision>
    <origin xyz="-0.01783 -0.235685 -0.130769" rpy="0 0 0"/>
    <geometry>
      <mesh filename="package://rhexa_description/meshes/Joint3_1.stl" scale="0.001 0.001 0.001"/>
    </geometry>
  </collision>
</link>

<link name="Joint4_1">
  <inertial>
    <origin xyz="0.034115491169552516 0.05000047440104943 4.961988445129073e-07" rpy="0 0 0"/>
    <mass value="1.0598755331662075"/>
    <inertia ixx="0.002025" iyy="0.000454" izz="0.002183" ixy="0.0" iyz="-0.0" ixz="0.0"/>
  </inertial>
  <visual>
    <origin xyz="-0.00133 -0.385685 -0.130769" rpy="0 0 0"/>
    <geometry>
      <mesh filename="package://rhexa_description/meshes/Joint4_1.stl" scale="0.001 0.001 0.001"/>
    </geometry>
    <material name="silver"/>
  </visual>
  <collision>
    <origin xyz="-0.00133 -0.385685 -0.130769" rpy="0 0 0"/>
    <geometry>
      <mesh filename="package://rhexa_description/meshes/Joint4_1.stl" scale="0.001 0.001 0.001"/>
    </geometry>
  </collision>
</link>

<link name="Joint5_1">
  <inertial>
    <origin xyz="-0.02955725242912048 0.0745916746018313 4.961988424034836e-07" rpy="0 0 0"/>
    <mass value="0.32403192309695955"/>
    <inertia ixx="0.0006" iyy="0.000202" izz="0.000602" ixy="1.1e-05" iyz="0.0" ixz="-0.0"/>
  </inertial>
  <visual>
    <origin xyz="-0.01783 -0.485685 -0.130769" rpy="0 0 0"/>
    <geometry>
      <mesh filename="package://rhexa_description/meshes/Joint5_1.stl" scale="0.001 0.001 0.001"/>
    </geometry>
    <material name="silver"/>
  </visual>
  <collision>
    <origin xyz="-0.01783 -0.485685 -0.130769" rpy="0 0 0"/>
    <geometry>
      <mesh filename="package://rhexa_description/meshes/Joint5_1.stl" scale="0.001 0.001 0.001"/>
    </geometry>
  </collision>
</link>

<link name="HEXA_link6_1_v1_1">
  <inertial>
    <origin xyz="-9.130079979199901e-08 0.08926834062141131 4.96198841848372e-07" rpy="0 0 0"/>
    <mass value="0.2540678574498573"/>
    <inertia ixx="0.000686" iyy="0.00011" izz="0.000695" ixy="-0.0" iyz="0.0" ixz="-0.0"/>
  </inertial>
  <visual>
    <origin xyz="0.01217 -0.513685 -0.130769" rpy="0 0 0"/>
    <geometry>
      <mesh filename="package://rhexa_description/meshes/HEXA_link6_1_v1_1.stl" scale="0.001 0.001 0.001"/>
    </geometry>
    <material name="silver"/>
  </visual>
  <collision>
    <origin xyz="0.01217 -0.513685 -0.130769" rpy="0 0 0"/>
    <geometry>
      <mesh filename="package://rhexa_description/meshes/HEXA_link6_1_v1_1.stl" scale="0.001 0.001 0.001"/>
    </geometry>
  </collision>
</link>

<joint name="Rígida1" type="fixed">
  <origin xyz="0.0 0.0 0.07" rpy="0 0 0"/>
  <parent link="base_link"/>
  <child link="Componente5_1"/>
</joint>

<joint name="Revolución2" type="revolute">
  <origin xyz="0.0 0.0 0.02" rpy="0 0 0"/>
  <parent link="Componente5_1"/>
  <child link="Joint1_1"/>
  <axis xyz="0.0 0.0 1.0"/>
  <limit upper="6.283185" lower="0.0" effort="100" velocity="100"/>
</joint>

<joint name="Revolución3" type="revolute">
  <origin xyz="-0.016501 0.035737 0.036223" rpy="0 0 0"/>
  <parent link="Joint1_1"/>
  <child link="Joint2_1"/>
  <axis xyz="1.0 0.0 0.0"/>
  <limit upper="2.792527" lower="0.0" effort="100" velocity="100"/>
</joint>

<joint name="Revolución4" type="revolute">
  <origin xyz="0.034331 0.199948 0.004546" rpy="0 0 0"/>
  <parent link="Joint2_1"/>
  <child link="Joint3_1"/>
  <axis xyz="-1.0 0.0 0.0"/>
  <limit upper="2.268928" lower="-2.617994" effort="100" velocity="100"/>
</joint>

<joint name="Revolución5" type="revolute">
  <origin xyz="-0.0165 0.15 0.0" rpy="0 0 0"/>
  <parent link="Joint3_1"/>
  <child link="Joint4_1"/>
  <axis xyz="-1.0 -0.0 0.0"/>
  <limit upper="2.617994" lower="-2.617994" effort="100" velocity="100"/>
</joint>

<joint name="Revolución6" type="revolute">
  <origin xyz="0.0165 0.1 0.0" rpy="0 0 0"/>
  <parent link="Joint4_1"/>
  <child link="Joint5_1"/>
  <axis xyz="1.0 0.0 -0.0"/>
  <limit upper="2.617994" lower="-2.443461" effort="100" velocity="100"/>
</joint>

<joint name="Corredera7" type="prismatic">
  <origin xyz="-0.03 0.028 0.0" rpy="0 0 0"/>
  <parent link="Joint5_1"/>
  <child link="HEXA_link6_1_v1_1"/>
  <axis xyz="-0.0 1.0 -0.0"/>
  <limit upper="0.112" lower="0.0" effort="100" velocity="100"/>
</joint>

</robot>
